Workbook
Name NativeTimeline_Sale_Date: #N/A
Name Slicer_Loyalty_Card: #N/A
Name Slicer_Membership_Type: #N/A

Sheet sales
A1: Sale_ID | B1: Sale_Date | C1: Customer_ID | D1: Product_SKU | E1: Units_Sold | F1: Customer_Name | G1: Customer_Email | H1: Ship_Country | I1: Book_Genre | J1: Price_Per_Unit | K1: Revenue | L1: Loyalty_Card | M1: Membership_Type | N1: Book_title
A2: SALE-004-2023 | B2: 44941 | C2: CUST-1859 | D2: BK-782355 | E2: 4 | F2: =_xlfn.XLOOKUP(C2,customers!$A$1:$A$983,customers!$B$1:$B$983,,0) -> William Hill | G2: {=_xlfn.XLOOKUP(C2,customers!A2:$A$983,customers!$C$2:$C$983,,0)} -> william.hill841@outlook.com | H2: =IF(_xlfn.XLOOKUP(C2,customers!$A:$A,customers!$G:$G,,0)=0,"",_xlfn.XLOOKUP(C2,customers!$A:$A,customers!$G:$G,,0)) -> Norway | I2: =IF(_xlfn.XLOOKUP(D2,product!$A:$A,product!$E:$E,,0)=0,"",_xlfn.XLOOKUP(D2,product!$A:$A,product!$E:$E,,0)) -> TECH | J2: =IF(_xlfn.XLOOKUP(D2,product!$A:$A,product!$D:$D,,0)=0,"",_xlfn.XLOOKUP(D2,product!$A:$A,product!$D:$D,,0)) -> 34.35 | K2: =J2*E2 -> 137.4 | L2: =IF(_xlfn.XLOOKUP(D2,product!$A:$A,product!$F:$F,,0)=0,"",_xlfn.XLOOKUP(D2,product!$A:$A,product!$F:$F,,0)) -> Yes | M2: =IF(_xlfn.XLOOKUP(D2,product!$A:$A,product!G:G,,0)=0,"",_xlfn.XLOOKUP(D2,product!$A:$A,product!G:G,,0)) -> None | N2: =IF(_xlfn.XLOOKUP(D2,product!$A:$A,product!$B:$B,,0)=0,"",_xlfn.XLOOKUP(D2,product!$A:$A,product!$B:$B,,0)) -> Forest Data
A3: SALE-026-2023 | B3: 45007 | C3: CUST-1373 | D3: BK-811569 | E3: 2 | F3: =_xlfn.XLOOKUP(C3,customers!$A$1:$A$983,customers!$B$1:$B$983,,0) -> Laura Martinez | G3: =_xlfn.XLOOKUP(C3,customers!$A:$A,customers!$C:$C,,0) -> laura.martinez355@hotmail.com | H3: =IF(_xlfn.XLOOKUP(C3,customers!$A:$A,customers!$G:$G,,0)=0,"",_xlfn.XLOOKUP(C3,customers!$A:$A,customers!$G:$G,,0)) -> Sweden | I3: =IF(_xlfn.XLOOKUP(D3,product!$A:$A,product!$E:$E,,0)=0,"",_xlfn.XLOOKUP(D3,product!$A:$A,product!$E:$E,,0)) -> BUSINESS | J3: =IF(_xlfn.XLOOKUP(D3,product!$A:$A,product!$D:$D,,0)=0,"",_xlfn.XLOOKUP(D3,product!$A:$A,product!$D:$D,,0)) -> 33.63 | K3: =J3*E3 -> 67.26 | L3: =IF(_xlfn.XLOOKUP(D3,product!$A:$A,product!$F:$F,,0)=0,"",_xlfn.XLOOKUP(D3,product!$A:$A,product!$F:$F,,0)) -> No | M3: =IF(_xlfn.XLOOKUP(D3,product!$A:$A,product!G:G,,0)=0,"",_xlfn.XLOOKUP(D3,product!$A:$A,product!G:G,,0)) -> Gold | N3: =IF(_xlfn.XLOOKUP(D3,product!$A:$A,product!$B:$B,,0)=0,"",_xlfn.XLOOKUP(D3,product!$A:$A,product!$B:$B,,0)) -> Quantum Power
A4: SALE-043-2023 | B4: 44967 | C4: CUST-1559 | D4: BK-799901 | E4: 2 | F4: =_xlfn.XLOOKUP(C4,customers!$A$1:$A$983,customers!$B$1:$B$983,,0) -> Paul Thomas | G4: =_xlfn.XLOOKUP(C4,customers!$A:$A,customers!$C:$C,,0) -> paul.thomas541@hotmail.com | H4: =IF(_xlfn.XLOOKUP(C4,customers!$A:$A,customers!$G:$G,,0)=0,"",_xlfn.XLOOKUP(C4,customers!$A:$A,customers!$G:$G,,0)) -> USA | I4: =IF(_xlfn.XLOOKUP(D4,product!$A:$A,product!$E:$E,,0)=0,"",_xlfn.XLOOKUP(D4,product!$A:$A,product!$E:$E,,0)) -> BUSINESS | J4: =IF(_xlfn.XLOOKUP(D4,product!$A:$A,product!$D:$D,,0)=0,"",_xlfn.XLOOKUP(D4,product!$A:$A,product!$D:$D,,0)) -> 31.32 | K4: =J4*E4 -> 62.64 | L4: =IF(_xlfn.XLOOKUP(D4,product!$A:$A,product!$F:$F,,0)=0,"",_xlfn.XLOOKUP(D4,product!$A:$A,product!$F:$F,,0)) -> No | M4: =IF(_xlfn.XLOOKUP(D4,product!$A:$A,product!G:G,,0)=0,"",_xlfn.XLOOKUP(D4,product!$A:$A,product!G:G,,0)) -> Silver | N4: =IF(_xlfn.XLOOKUP(D4,product!$A:$A,product!$B:$B,,0)=0,"",_xlfn.XLOOKUP(D4,product!$A:$A,product!$B:$B,,0)) -> Mind Journey
A5: SALE-060-2023 | B5: 45064 | C5: CUST-1245 | D5: BK-735269 | E5: 2 | F5: =_xlfn.XLOOKUP(C5,customers!$A$1:$A$983,customers!$B$1:$B$983,,0) -> Emma Lopez | G5: =_xlfn.XLOOKUP(C5,customers!$A:$A,customers!$C:$C,,0) -> emma.lopez227@gmail.com | H5: =IF(_xlfn.XLOOKUP(C5,customers!$A:$A,customers!$G:$G,,0)=0,"",_xlfn.XLOOKUP(C5,customers!$A:$A,customers!$G:$G,,0)) -> Pakistan | I5: =IF(_xlfn.XLOOKUP(D5,product!$A:$A,product!$E:$E,,0)=0,"",_xlfn.XLOOKUP(D5,product!$A:$A,product!$E:$E,,0)) -> BUSINESS | J5: =IF(_xlfn.XLOOKUP(D5,product!$A:$A,product!$D:$D,,0)=0,"",_xlfn.XLOOKUP(D5,product!$A:$A,product!$D:$D,,0)) -> 30.46 | K5: =J5*E5 -> 60.92 | L5: =IF(_xlfn.XLOOKUP(D5,product!$A:$A,product!$F:$F,,0)=0,"",_xlfn.XLOOKUP(D5,product!$A:$A,product!$F:$F,,0)) -> No | M5: =IF(_xlfn.XLOOKUP(D5,product!$A:$A,product!G:G,,0)=0,"",_xlfn.XLOOKUP(D5,product!$A:$A,product!G:G,,0)) -> None | N5: =IF(_xlfn.XLOOKUP(D5,product!$A:$A,product!$B:$B,,0)=0,"",_xlfn.XLOOKUP(D5,product!$A:$A,product!$B:$B,,0)) -> Journey Forest
A6: SALE-077-2023 | B6: 45110 | C6: CUST-1253 | D6: BK-582215 | E6: 2 | F6: =_xlfn.XLOOKUP(C6,customers!$A$1:$A$983,customers!$B$1:$B$983,,0) -> Zoe Lee | G6: =_xlfn.XLOOKUP(C6,customers!$A:$A,customers!$C:$C,,0) -> zoe.lee235@outlook.com | H6: =IF(_xlfn.XLOOKUP(C6,customers!$A:$A,customers!$G:$G,,0)=0,"",_xlfn.XLOOKUP(C6,customers!$A:$A,customers!$G:$G,,0)) -> USA | I6: =IF(_xlfn.XLOOKUP(D6,product!$A:$A,product!$E:$E,,0)=0,"",_xlfn.XLOOKUP(D6,product!$A:$A,product!$E:$E,,0)) -> BUSINESS | J6: =IF(_xlfn.XLOOKUP(D6,product!$A:$A,product!$D:$D,,0)=0,"",_xlfn.XLOOKUP(D6,product!$A:$A,product!$D:$D,,0)) -> 31.45 | K6: =J6*E6 -> 62.9 | L6: =IF(_xlfn.XLOOKUP(D6,product!$A:$A,product!$F:$F,,0)=0,"",_xlfn.XLOOKUP(D6,product!$A:$A,product!$F:$F,,0)) -> No | M6: =IF(_xlfn.XLOOKUP(D6,product!$A:$A,product!G:G,,0)=0,"",_xlfn.XLOOKUP(D6,product!$A:$A,product!G:G,,0)) -> Silver | N6: =IF(_xlfn.XLOOKUP(D6,product!$A:$A,product!$B:$B,,0)=0,"",_xlfn.XLOOKUP(D6,product!$A:$A,product!$B:$B,,0)) -> Secrets Forest
A7: SALE-094-2023 | B7: 45549 | C7: CUST-1036 | D7: BK-921200 | E7: 1 | F7: =_xlfn.XLOOKUP(C7,customers!$A$1:$A$983,customers!$B$1:$B$983,,0) -> Emily Anderson | G7: =_xlfn.XLOOKUP(C7,customers!$A:$A,customers!$C:$C,,0) -> emily.anderson18@gmail.com | H7: =IF(_xlfn.XLOOKUP(C7,customers!$A:$A,customers!$G:$G,,0)=0,"",_xlfn.XLOOKUP(C7,customers!$A:$A,customers!$G:$G,,0)) -> Germany | I7: =IF(_xlfn.XLOOKUP(D7,product!$A:$A,product!$E:$E,,0)=0,"",_xlfn.XLOOKUP(D7,product!$A:$A,product!$E:$E,,0)) -> FICTION | J7: =IF(_xlfn.XLOOKUP(D7,product!$A:$A,product!$D:$D,,0)=0,"",_xlfn.XLOOKUP(D7,product!$A:$A,product!$D:$D,,0)) -> 17.41 | K7: =J7*E7 -> 17.41 | L7: =IF(_xlfn.XLOOKUP(D7,product!$A:$A,product!$F:$F,,0)=0,"",_xlfn.XLOOKUP(D7,product!$A:$A,product!$F:$F,,0)) -> No | M7: =IF(_xlfn.XLOOKUP(D7,product!$A:$A,product!G:G,,0)=0,"",_xlfn.XLOOKUP(D7,product!$A:$A,product!G:G,,0)) -> None | N7: =IF(_xlfn.XLOOKUP(D7,product!$A:$A,product!$B:$B,,0)=0,"",_xlfn.XLOOKUP(D7,product!$A:$A,product!$B:$B,,0)) -> Forest Silent
A8: SALE-111-2023 | B8: 45255 | C8: CUST-1458 | D8: BK-110284 | E8: 1 | F8: =_xlfn.XLOOKUP(C8,customers!$A$1:$A$983,customers!$B$1:$B$983,,0) -> James Allen | G8: =_xlfn.XLOOKUP(C8,customers!$A:$A,customers!$C:$C,,0) -> james.allen440@outlook.com | H8: =IF(_xlfn.XLOOKUP(C8,customers!$A:$A,customers!$G:$G,,0)=0,"",_xlfn.XLOOKUP(C8,customers!$A:$A,customers!$G:$G,,0)) -> Spain | I8: =IF(_xlfn.XLOOKUP(D8,product!$A:$A,product!$E:$E,,0)=0,"",_xlfn.XLOOKUP(D8,product!$A:$A,product!$E:$E,,0)) -> TECH | J8: =IF(_xlfn.XLOOKUP(D8,product!$A:$A,product!$D:$D,,0)=0,"",_xlfn.XLOOKUP(D8,product!$A:$A,product!$D:$D,,0)) -> 11.13 | K8: =J8*E8 -> 11.13 | L8: =IF(_xlfn.XLOOKUP(D8,product!$A:$A,product!$F:$F,,0)=0,"",_xlfn.XLOOKUP(D8,product!$A:$A,product!$F:$F,,0)) -> Yes | M8: =IF(_xlfn.XLOOKUP(D8,product!$A:$A,product!G:G,,0)=0,"",_xlfn.XLOOKUP(D8,product!$A:$A,product!G:G,,0)) -> Silver | N8: =IF(_xlfn.XLOOKUP(D8,product!$A:$A,product!$B:$B,,0)=0,"",_xlfn.XLOOKUP(D8,product!$A:$A,product!$B:$B,,0)) -> Data Mind
A9: SALE-128-2023 | B9: 45350 | C9: CUST-1418 | D9: BK-253635 | E9: 1 | F9: =_xlfn.XLOOKUP(C9,customers!$A$1:$A$983,customers!$B$1:$B$983,,0) -> Thomas Hill | G9: =_xlfn.XLOOKUP(C9,customers!$A:$A,customers!$C:$C,,0) -> thomas.hill400@yahoo.com | H9: =IF(_xlfn.XLOOKUP(C9,customers!$A:$A,customers!$G:$G,,0)=0,"",_xlfn.XLOOKUP(C9,customers!$A:$A,customers!$G:$G,,0)) -> Sweden | I9: =IF(_xlfn.XLOOKUP(D9,product!$A:$A,product!$E:$E,,0)=0,"",_xlfn.XLOOKUP(D9,product!$A:$A,product!$E:$E,,0)) -> BUSINESS | J9: =IF(_xlfn.XLOOKUP(D9,product!$A:$A,product!$D:$D,,0)=0,"",_xlfn.XLOOKUP(D9,product!$A:$A,product!$D:$D,,0)) -> 31.29 | K9: =J9*E9 -> 31.29 | L9: =IF(_xlfn.XLOOKUP(D9,product!$A:$A,product!$F:$F,,0)=0,"",_xlfn.XLOOKUP(D9,product!$A:$A,product!$F:$F,,0)) -> Yes | M9: =IF(_xlfn.XLOOKUP(D9,product!$A:$A,product!G:G,,0)=0,"",_xlfn.XLOOKUP(D9,product!$A:$A,product!G:G,,0)) -> None | N9: =IF(_xlfn.XLOOKUP(D9,product!$A:$A,product!$B:$B,,0)=0,"",_xlfn.XLOOKUP(D9,product!$A:$A,product!$B:$B,,0)) -> Secrets Quantum
A10: SALE-145-2023 | B10: 45157 | C10: CUST-1398 | D10: BK-633345 | E10: 1 | F10: =_xlfn.XLOOKUP(C10,customers!$A$1:$A$983,customers!$B$1:$B$983,,0) -> Peter Adams | G10: =_xlfn.XLOOKUP(C10,customers!$A:$A,customers!$C:$C,,0) -> peter.adams380@gmail.com | H10: =IF(_xlfn.XLOOKUP(C10,customers!$A:$A,customers!$G:$G,,0)=0,"",_xlfn.XLOOKUP(C10,customers!$A:$A,customers!$G:$G,,0)) -> UAE | I10: =IF(_xlfn.XLOOKUP(D10,product!$A:$A,product!$E:$E,,0)=0,"",_xlfn.XLOOKUP(D10,product!$A:$A,product!$E:$E,,0)) -> BUSINESS | J10: =IF(_xlfn.XLOOKUP(D10,product!$A:$A,product!$D:$D,,0)=0,"",_xlfn.XLOOKUP(D10,product!$A:$A,product!$D:$D,,0)) -> 10.51 | K10: =J10*E10 -> 10.51 | L10: =IF(_xlfn.XLOOKUP(D10,product!$A:$A,product!$F:$F,,0)=0,"",_xlfn.XLOOKUP(D10,product!$A:$A,product!$F:$F,,0)) -> Yes | M10: =IF(_xlfn.XLOOKUP(D10,product!$A:$A,product!G:G,,0)=0,"",_xlfn.XLOOKUP(D10,product!$A:$A,product!G:G,,0)) -> None | N10: =IF(_xlfn.XLOOKUP(D10,product!$A:$A,product!$B:$B,,0)=0,"",_xlfn.XLOOKUP(D10,product!$A:$A,product!$B:$B,,0)) -> Secrets Data
A11: SALE-162-2023 | B11: 45387 | C11: CUST-1733 | D11: BK-640596 | E11: 1 | F11: =_xlfn.XLOOKUP(C11,customers!$A$1:$A$983,customers!$B$1:$B$983,,0) -> Emily Young | G11: =_xlfn.XLOOKUP(C11,customers!$A:$A,customers!$C:$C,,0) -> emily.young715@hotmail.com | H11: =IF(_xlfn.XLOOKUP(C11,customers!$A:$A,customers!$G:$G,,0)=0,"",_xlfn.XLOOKUP(C11,customers!$A:$A,customers!$G:$G,,0)) -> Sweden | I11: =IF(_xlfn.XLOOKUP(D11,product!$A:$A,product!$E:$E,,0)=0,"",_xlfn.XLOOKUP(D11,product!$A:$A,product!$E:$E,,0)) -> FICTION | J11: =IF(_xlfn.XLOOKUP(D11,product!$A:$A,product!$D:$D,,0)=0,"",_xlfn.XLOOKUP(D11,product!$A:$A,product!$D:$D,,0)) -> 23.32 | K11: =J11*E11 -> 23.32 | L11: =IF(_xlfn.XLOOKUP(D11,product!$A:$A,product!$F:$F,,0)=0,"",_xlfn.XLOOKUP(D11,product!$A:$A,product!$F:$F,,0)) -> Yes | M11: =IF(_xlfn.XLOOKUP(D11,product!$A:$A,product!G:G,,0)=0,"",_xlfn.XLOOKUP(D11,product!$A:$A,product!G:G,,0)) -> Silver | N11: =IF(_xlfn.XLOOKUP(D11,product!$A:$A,product!$B:$B,,0)=0,"",_xlfn.XLOOKUP(D11,product!$A:$A,product!$B:$B,,0)) -> Silent Future
A12: SALE-179-2023 | B12: 45268 | C12: CUST-1971 | D12: BK-746815 | E12: 1 | F12: =_xlfn.XLOOKUP(C12,customers!$A$1:$A$983,customers!$B$1:$B$983,,0) -> George Allen | G12: =_xlfn.XLOOKUP(C12,customers!$A:$A,customers!$C:$C,,0) -> george.allen953@hotmail.com | H12: =IF(_xlfn.XLOOKUP(C12,customers!$A:$A,customers!$G:$G,,0)=0,"",_xlfn.XLOOKUP(C12,customers!$A:$A,customers!$G:$G,,0)) -> Russia | I12: =IF(_xlfn.XLOOKUP(D12,product!$A:$A,product!$E:$E,,0)=0,"",_xlfn.XLOOKUP(D12,product!$A:$A,product!$E:$E,,0)) -> TECH | J12: =IF(_xlfn.XLOOKUP(D12,product!$A:$A,product!$D:$D,,0)=0,"",_xlfn.XLOOKUP(D12,product!$A:$A,product!$D:$D,,0)) -> 39.22 | K12: =J12*E12 -> 39.22 | L12: =IF(_xlfn.XLOOKUP(D12,product!$A:$A,product!$F:$F,,0)=0,"",_xlfn.XLOOKUP(D12,product!$A:$A,product!$F:$F,,0)) -> Yes | M12: =IF(_xlfn.XLOOKUP(D12,product!$A:$A,product!G:G,,0)=0,"",_xlfn.XLOOKUP(D12,product!$A:$A,product!G:G,,0)) -> Silver | N12: =IF(_xlfn.XLOOKUP(D12,product!$A:$A,product!$B:$B,,0)=0,"",_xlfn.XLOOKUP(D12,product!$A:$A,product!$B:$B,,0)) -> Science Future
A13: SALE-196-2023 | B13: 45464 | C13: CUST-1252 | D13: BK-664582 | E13: 1 | F13: =_xlfn.XLOOKUP(C13,customers!$A$1:$A$983,customers!$B$1:$B$983,,0) -> Andrew Jackson | G13: =_xlfn.XLOOKUP(C13,customers!$A:$A,customers!$C:$C,,0) -> andrew.jackson234@gmail.com | H13: =IF(_xlfn.XLOOKUP(C13,customers!$A:$A,customers!$G:$G,,0)=0,"",_xlfn.XLOOKUP(C13,customers!$A:$A,customers!$G:$G,,0)) -> Germany | I13: =IF(_xlfn.XLOOKUP(D13,product!$A:$A,product!$E:$E,,0)=0,"",_xlfn.XLOOKUP(D13,product!$A:$A,product!$E:$E,,0)) -> FICTION | J13: =IF(_xlfn.XLOOKUP(D13,product!$A:$A,product!$D:$D,,0)=0,"",_xlfn.XLOOKUP(D13,product!$A:$A,product!$D:$D,,0)) -> 28.12 | K13: =J13*E13 -> 28.12 | L13: =IF(_xlfn.XLOOKUP(D13,product!$A:$A,product!$F:$F,,0)=0,"",_xlfn.XLOOKUP(D13,product!$A:$A,product!$F:$F,,0)) -> No | M13: =IF(_xlfn.XLOOKUP(D13,product!$A:$A,product!G:G,,0)=0,"",_xlfn.XLOOKUP(D13,product!$A:$A,product!G:G,,0)) -> Gold | N13: =IF(_xlfn.XLOOKUP(D13,product!$A:$A,product!$B:$B,,0)=0,"",_xlfn.XLOOKUP(D13,product!$A:$A,product!$B:$B,,0)) -> Secrets Data
A14: SALE-213-2023 | B14: 45229 | C14: CUST-1748 | D14: BK-372999 | E14: 1 | F14: =_xlfn.XLOOKUP(C14,customers!$A$1:$A$983,customers!$B$1:$B$983,,0) -> Emma Walker | G14: =_xlfn.XLOOKUP(C14,customers!$A:$A,customers!$C:$C,,0) -> emma.walker730@yahoo.com | H14: =IF(_xlfn.XLOOKUP(C14,customers!$A:$A,customers!$G:$G,,0)=0,"",_xlfn.XLOOKUP(C14,customers!$A:$A,customers!$G:$G,,0)) -> USA | I14: =IF(_xlfn.XLOOKUP(D14,product!$A:$A,product!$E:$E,,0)=0,"",_xlfn.XLOOKUP(D14,product!$A:$A,product!$E:$E,,0)) -> TECH | J14: =IF(_xlfn.XLOOKUP(D14,product!$A:$A,product!$D:$D,,0)=0,"",_xlfn.XLOOKUP(D14,product!$A:$A,product!$D:$D,,0)) -> 20.59 | K14: =J14*E14 -> 20.59 | L14: =IF(_xlfn.XLOOKUP(D14,product!$A:$A,product!$F:$F,,0)=0,"",_xlfn.XLOOKUP(D14,product!$A:$A,product!$F:$F,,0)) -> Yes | M14: =IF(_xlfn.XLOOKUP(D14,product!$A:$A,product!G:G,,0)=0,"",_xlfn.XLOOKUP(D14,product!$A:$A,product!G:G,,0)) -> Silver | N14: =IF(_xlfn.XLOOKUP(D14,product!$A:$A,product!$B:$B,,0)=0,"",_xlfn.XLOOKUP(D14,product!$A:$A,product!$B:$B,,0)) -> Data Quantum
... A983: SALE-970-2023 | B983: 45439 | C983: CUST-1358 | D983: BK-444961 | E983: 2 | F983: =_xlfn.XLOOKUP(C983,customers!$A$1:$A$983,customers!$B$1:$B$983,,0) -> Peter Wright | G983: =_xlfn.XLOOKUP(C983,customers!$A:$A,customers!$C:$C,,0) -> peter.wright340@gmail.com | H983: =IF(_xlfn.XLOOKUP(C983,customers!$A:$A,customers!$G:$G,,0)=0,"",_xlfn.XLOOKUP(C983,customers!$A:$A,customers!$G:$G,,0)) -> Japan | I983: =IF(_xlfn.XLOOKUP(D983,product!$A:$A,product!$E:$E,,0)=0,"",_xlfn.XLOOKUP(D983,product!$A:$A,product!$E:$E,,0)) -> FICTION | J983: =IF(_xlfn.XLOOKUP(D983,product!$A:$A,product!$D:$D,,0)=0,"",_xlfn.XLOOKUP(D983,product!$A:$A,product!$D:$D,,0)) -> 39.61 | K983: =J983*E983 -> 79.22 | L983: =IF(_xlfn.XLOOKUP(D983,product!$A:$A,product!$F:$F,,0)=0,"",_xlfn.XLOOKUP(D983,product!$A:$A,product!$F:$F,,0)) -> No | M983: =IF(_xlfn.XLOOKUP(D983,product!$A:$A,product!G:G,,0)=0,"",_xlfn.XLOOKUP(D983,product!$A:$A,product!G:G,,0)) -> Gold | N983: =IF(_xlfn.XLOOKUP(D983,product!$A:$A,product!$B:$B,,0)=0,"",_xlfn.XLOOKUP(D983,product!$A:$A,product!$B:$B,,0)) -> Secrets Forest

Sheet customers
A1: Customer_Ref | B1: Full_Name | C1: Email_Address | D1: Phone_Number | E1: Delivery_Address | F1: City | G1: Country | H1: Postal_Code | I1: Membership_Level | J1: Join_Date
A2: CUST-1019 | B2: Joshua Green | C2: joshua.green1@hotmail.com | D2: +1 (305) 555-9012 | E2: Ocean Drive 2600 | F2: Miami | G2: USA | H2: 33139 | I2: Silver | J2: 44893 | M2: =V2&" "&W2
A3: CUST-1020 | B3: Amelia Martin | C3: amelia.martin2@hotmail.com | D3: +971 4 567 8901 | E3: Sheikh Zayed Road 99 | F3: Dubai | G3: UAE | H3: 123456 | I3: Bronze | J3: 45146
A4: CUST-1021 | B4: David Martinez | C4: david.martinez3@yahoo.com | D4: +81 3 6789-0123 | E4: Shibuya 41-24-12 | F4: Tokyo | G4: Japan | H4: 150-0002 | I4: Gold | J4: 44497 | M4: =V4&" "&W4
A5: CUST-1022 | B5: Ella Taylor | C5: ella.taylor4@gmail.com | D5: +46 40 456 78 | E5: Stortorget 225 | F5: Malmö | G5: Sweden | H5: 211 34 | I5: Silver | J5: 44907 | M5: =V5&" "&W5
A6: CUST-1023 | B6: Steven Rodriguez | C6: steven.rodriguez5@yahoo.com | D6: +20 2 8901234 | E6: Dokki 106 | F6: Cairo | G6: Egypt | H6: 12311 | I6: Bronze | J6: 45119 | M6: =V6&" "&W6
A7: CUST-1024 | B7: Thomas Young | C7: thomas.young6@hotmail.com | D7: +34 93 789 01 23 | E7: Passeig de Gràcia 2200 | F7: Barcelona | G7: Spain | H7: 8008 | I7: Gold | J7: 44518 | M7: =V7&" "&W7
A8: CUST-1025 | B8: Lily Johnson | C8: lily.johnson7@outlook.com | D8: +81 45 678-9012 | E8: Aoba-ku 27-1-1 | F8: Yokohama | H8: 225-0001 | I8: Silver | J8: 44812 | M8: =V8&" "&W8
A9: CUST-1026 | B9: Chloe Wright | C9: chloe.wright8@hotmail.com | D9: +34 91 012 34 56 | E9: Calle de Serrano 4100 | F9: Madrid | G9: Spain | H9: 28006 | I9: Bronze | J9: 45105 | M9: =V9&" "&W9
A10: CUST-1027 | B10: Daniel Lewis | C10: daniel.lewis9@hotmail.com | D10: +49 30 678901 | E10: Alexanderplatz 310 | F10: Berlin | G10: Germany | H10: 10178 | I10: Gold | J10: 44552 | M10: =V10&" "&W10
A11: CUST-1028 | B11: Isabella Jackson | C11: isabella.jackson10@outlook.com | D11: +1 (404) 555-9012 | E11: Peachtree Street 1700 | F11: Atlanta | G11: USA | H11: 30303 | I11: Silver | J11: 44852 | M11: =V11&" "&W11
A12: CUST-1029 | B12: Joshua Hall | C12: joshua.hall11@outlook.com | D12: +92 21 2345678 | E12: Clifton 115 | F12: Karachi | G12: Pakistan | H12: 75600 | I12: Bronze | J12: 45068 | M12: =V12&" "&W12
A13: CUST-1030 | B13: Anna Garcia | C13: anna.garcia12@outlook.com | D13: +81 3 5678-9012 | E13: Chiyoda 40-1-1 | F13: Tokyo | G13: Japan | H13: 100-0001 | I13: Gold | J13: 44447 | M13: =V13&" "&W13
A14: CUST-1031 | B14: Steven Scott | C14: steven.scott13@hotmail.com | D14: +46 31 456 78 | E14: Kungsportsavenyn 230 | F14: Gothenburg | G14: Sweden | H14: 411 36 | I14: Silver | J14: 44877 | M14: =V14&" "&W14
A15: CUST-1032 | B15: Mia Jackson | C15: mia.jackson14@yahoo.com | D15: +20 2 7890123 | E15: Mohandessin 105 | F15: Cairo | G15: Egypt | H15: 12311 | I15: Bronze | J15: 45031 | M15: =V15&" "&W15
A16: CUST-1033 | B16: William Johnson | C16: william.johnson15@gmail.com | D16: +34 93 678 90 12 | E16: Diagonal 4100 | F16: Barcelona | G16: Spain | H16: 8018 | I16: Gold | J16: 44491 | M16: =V16&" "&W16
A17: CUST-1034 | B17: Ryan White | C17: ryan.white16@hotmail.com | D17: +81 45 567-8901 | E17: Nishi-ku 28-1-1 | F17: Yokohama | G17: Japan | H17: 220-0001 | I17: Silver | J17: 44913 | M17: =V17&" "&W17
A18: CUST-1035 | B18: Paul Garcia | C18: paul.garcia17@hotmail.com | D18: +34 91 901 23 45 | E18: Calle de Goya 4000 | F18: Madrid | G18: Spain | H18: 28001 | I18: Bronze | J18: 44993 | M18: =V18&" "&W18
A19: CUST-1036 | B19: Emily Anderson | C19: emily.anderson18@gmail.com | D19: +49 30 567890 | E19: Potsdamer Platz 160 | F19: Berlin | G19: Germany | H19: 10785 | I19: Gold | J19: 44512 | M19: =V19&" "&W19
A20: CUST-1037 | B20: Ava Young | C20: ava.young19@outlook.com | D20: +1 (214) 555-9012 | E20: Main Street 2100 | F20: Dallas | G20: USA | H20: 75202 | I20: Silver | J20: 44829 | M20: =V20&" "&W20
A21: CUST-1038 | B21: Mark Garcia | C21: mark.garcia20@outlook.com | D21: +92 42 2345678 | E21: Cantt 114 | F21: Lahore | G21: Pakistan | H21: 54810 | I21: Bronze | J21: 44979 | M21: =V21&" "&W21
A22: CUST-1039 | B22: Grace Johnson | C22: grace.johnson21@yahoo.com | D22: +81 3 4567-8901 | E22: Shibuya 40-24-12 | F22: Tokyo | G22: Japan | H22: 150-0002 | I22: Gold | J22: 44548 | M22: =V22&" "&W22
A23: CUST-1040 | B23: Ryan Baker | C23: ryan.baker22@yahoo.com | D23: +46 40 345 67 | E23: Stortorget 220 | F23: Malmö | G23: Sweden | H23: 211 34 | I23: Silver | J23: 44846 | M23: =V23&" "&W23
A24: CUST-1041 | B24: Michael Young | C24: michael.young23@yahoo.com | D24: +20 2 6789012 | E24: Heliopolis 106 | F24: Cairo | G24: Egypt | H24: 11341 | I24: Bronze | J24: 44944 | M24: =V24&" "&W24
A25: CUST-1042 | B25: Zoe Lopez | C25: zoe.lopez24@gmail.com | D25: +34 93 567 89 01 | E25: Passeig de Gràcia 2150 | F25: Barcelona | G25: Spain | H25: 8008 | I25: Gold | J25: 44451 | M25: =V25&" "&W25
A26: CUST-1043 | B26: Edward Scott | C26: edward.scott25@gmail.com | D26: +81 45 456-7890 | E26: Kanagawa 28-1-1 | F26: Yokohama | G26: Japan | H26: 220-0012 | I26: Silver | J26: 44887 | M26: =V26&" "&W26
A27: CUST-1044 | B27: Ella Taylor | C27: ella.taylor26@yahoo.com | D27: +34 91 890 12 34 | E27: Calle de Serrano 4000 | F27: Madrid | G27: Spain | H27: 28006 | I27: Bronze | J27: 45268 | M27: =V27&" "&W27
A28: CUST-1045 | B28: Peter Allen | C28: peter.allen27@gmail.com | D28: +49 30 456789 | E28: Friedrichstraße 180 | F28: Berlin | G28: Germany | H28: 10117 | I28: Gold | J28: 44477 | M28: =V28&" "&W28
A29: CUST-1046 | B29: Daniel Hall | C29: daniel.hall28@gmail.com | D29: +1 (215) 555-8901 | E29: Market Street 1500 | F29: Philadelphia | G29: USA | H29: 19106 | I29: Silver | J29: 44862 | M29: =V29&" "&W29
A30: CUST-1047 | B30: Steven Adams | C30: steven.adams29@outlook.com | D30: +971 4 456 7890 | E30: Al Wasl Road 98 | F30: Dubai | G30: UAE | H30: 123456 | I30: Bronze | J30: 45242 | M30: =V30&" "&W30
A31: CUST-1048 | B31: Michael Johnson | C31: michael.johnson30@gmail.com | D31: +81 3 3456-7890 | E31: Chiyoda 39-1-1 | F31: Tokyo | G31: Japan | H31: 100-0001 | I31: Gold | J31: 44522 | M31: =V31&" "&W31
A32: CUST-1049 | B32: Isabella Wright | C32: isabella.wright31@yahoo.com | D32: +46 31 345 67 | E32: Kungsportsplatsen 21 | F32: Gothenburg | G32: Sweden | H32: 411 10 | I32: Silver | J32: 44826 | M32: =V32&" "&W32
A33: CUST-1050 | B33: Peter Martin | C33: peter.martin32@gmail.com | D33: +20 2 5678901 | E33: Sporting 104 | F33: Alexandria | G33: Egypt | H33: 21599 | I33: Bronze | J33: 45207 | M33: =V33&" "&W33
A34: CUST-1051 | B34: James Smith | C34: james.smith33@outlook.com | D34: +34 93 456 78 90 | E34: Diagonal 4000 | F34: Barcelona | G34: Spain | H34: 8018 | I34: Gold | J34: 44558 | M34: =V34&" "&W34
A35: CUST-1052 | B35: Emily Walker | C35: emily.walker34@hotmail.com | D35: +81 45 345-6789 | E35: Aoba-ku 26-1-1 | F35: Yokohama | G35: Japan | H35: 225-0001 | I35: Silver | J35: 44842 | M35: =V35&" "&W35
A36: CUST-1053 | B36: Zoe Smith | C36: zoe.smith35@gmail.com | D36: +34 91 789 01 23 | E36: Calle de Goya 3900 | F36: Madrid | G36: Spain | H36: 28001 | I36: Bronze | J36: 45191 | M36: =V36&" "&W36
A37: CUST-1054 | B37: Peter Thompson | C37: peter.thompson36@gmail.com | D37: +49 30 345678 | E37: Alexanderplatz 300 | F37: Berlin | G37: Germany | H37: 10178 | I37: Gold | J37: 44457 | M37: =V37&" "&W37
A38: CUST-1055 | B38: Sarah Hill | C38: sarah.hill37@outlook.com | D38: +1 (713) 555-8901 | E38: Main Street 2300 | F38: Houston | G38: USA | H38: 77002 | I38: Silver | J38: 44883 | M38: =V38&" "&W38
A39: CUST-1056 | B39: John Wright | C39: john.wright38@yahoo.com | D39: +92 21 1234567 | E39: Clifton 114 | F39: Karachi | G39: Pakistan | H39: 75600 | I39: Bronze | J39: 45146 | M39: =V39&" "&W39
A40: CUST-1057 | B40: Kevin Rodriguez | C40: kevin.rodriguez39@hotmail.com | D40: +81 3 2345-6789 | E40: Shibuya 39-24-12 | F40: Tokyo | G40: Japan | H40: 150-0002 | I40: Gold | J40: 44481 | M40: =V40&" "&W40
...

Sheet product
A1: Product_SKU | B1: Book_Title | C1: Author | D1: Retail_Price | E1: Category | F1: Loyalty_Card | G1: Membership_Type
A2: BK-782355 | B2: Forest Data | C2: Sophia Wilson | D2: 34.35 | E2: TECH | F2: Yes | G2: None
A3: BK-811569 | B3: Quantum Power | C3: Maria Lee | D3: 33.63 | E3: BUSINESS | F3: No | G3: Gold
A4: BK-799901 | B4: Mind Journey | C4: Lisa Lee | D4: 31.32 | E4: BUSINESS | F4: No | G4: Silver
A5: BK-735269 | B5: Journey Forest | C5: Sarah Taylor | D5: 30.46 | E5: BUSINESS | F5: No | G5: None
A6: BK-582215 | B6: Secrets Forest | C6: Emma Clark | D6: 31.45 | E6: BUSINESS | F6: No | G6: Silver
A7: BK-921200 | B7: Forest Silent | C7: Daniel Taylor | D7: 17.41 | E7: FICTION | F7: No | G7: None
A8: BK-110284 | B8: Data Mind | C8: Emma Clark | D8: 11.13 | E8: TECH | F8: Yes | G8: Silver
A9: BK-253635 | B9: Secrets Quantum | C9: Sophia Taylor | D9: 31.29 | E9: BUSINESS | F9: Yes | G9: None
A10: BK-633345 | B10: Secrets Data | C10: Michael Smith | D10: 10.51 | E10: BUSINESS | F10: Yes | G10: None
A11: BK-640596 | B11: Silent Future | C11: Daniel Park | D11: 23.32 | E11: FICTION | F11: Yes | G11: Silver
A12: BK-746815 | B12: Science Future | C12: David Taylor | D12: 39.22 | E12: TECH | F12: Yes | G12: Silver
A13: BK-664582 | B13: Secrets Data | C13: Sophia Walker | D13: 28.12 | E13: FICTION | F13: No | G13: Gold
... A983: BK-444961 | B983: Secrets Forest | C983: Emma Taylor | D983: 39.61 | E983: FICTION | F983: No | G983: Gold
A984: BK-523018 | B984: Quantum Mind | C984: Lisa Smith | D984: 34.06 | E984: BUSINESS

Sheet Pivot table 1
A2: Sum of Revenue | B2: Column Labels
A3: Row Labels | B3: BUSINESS | C3: FICTION | D3: HISTORY | E3: SCIENCE | F3: TECH | G3: Grand Total
A4: 2023
A5: janv | B5: 592.18 | C5: 290.97 | D5: 440.53 | E5: 350.78 | F5: 581.84 | G5: 2256.3
A6: févr | B6: 492.22 | C6: 364.62 | D6: 488.55 | E6: 706.38 | F6: 182.44 | G6: 2234.21
A7: mars | B7: 461.27 | C7: 373.34 | D7: 395.75 | E7: 397.21 | F7: 703.37 | G7: 2330.94
A8: avr | B8: 634.23 | C8: 292.76 | D8: 291.97 | E8: 385.28 | F8: 697.67 | G8: 2301.91
A9: mai | B9: 584.28 | C9: 440.3 | D9: 122.44 | E9: 829.8 | F9: 665.69 | G9: 2642.51
A10: juin | B10: 397.5 | C10: 260.08 | D10: 662.28 | E10: 403.9 | F10: 367.96 | G10: 2091.72
A11: juil | B11: 358.02 | C11: 526.86 | D11: 445.52 | E11: 389.11 | F11: 331.3 | G11: 2050.81
A12: août | B12: 406.43 | C12: 610.88 | D12: 527.96 | E12: 368.56 | F12: 757.25 | G12: 2671.08
A13: sept | B13: 127.52 | C13: 507.03 | D13: 804.08 | E13: 455.61 | F13: 519.01 | G13: 2413.25
A14: oct | B14: 671.97 | C14: 633.69 | D14: 358.88 | E14: 336.01 | F14: 307.16 | G14: 2307.71
A15: nov | B15: 484.62 | C15: 155.77 | D15: 352.19 | E15: 543.1 | F15: 748.58 | G15: 2284.26
A16: déc | B16: 341.55 | C16: 523.91 | D16: 638.47 | E16: 532.47 | F16: 278.29 | G16: 2314.69
A17: 2024
A18: janv | B18: 692.61 | C18: 417.62 | D18: 248.17 | E18: 436.73 | F18: 482.57 | G18: 2277.7
A19: févr | B19: 395.71 | C19: 446.29 | D19: 529.33 | E19: 599.49 | F19: 268.78 | G19: 2239.6
A20: mars | B20: 581.08 | C20: 743.16 | D20: 359.81 | E20: 349.78 | F20: 299.02 | G20: 2332.85
A21: avr | B21: 394.1 | C21: 682.06 | D21: 519.7 | E21: 437.83 | F21: 189.38 | G21: 2223.07
A22: mai | B22: 504.42 | C22: 386.76 | D22: 422.6 | E22: 681.89 | F22: 325.31 | G22: 2320.98
A23: juin | B23: 207.66 | C23: 683.85 | D23: 663.72 | E23: 266.17 | F23: 353.75 | G23: 2175.15
A24: juil | B24: 338.56 | C24: 487.45 | D24: 311.29 | E24: 539.86 | F24: 549.4 | G24: 2226.56
A25: août | B25: 400.64 | C25: 560.84 | D25: 334.84 | E25: 653.78 | F25: 247.43 | G25: 2197.53
A26: sept | B26: 373.59 | C26: 445.16 | D26: 454.11 | E26: 675.27 | F26: 90.32 | G26: 2038.45
A27: oct | B27: 151.08 | C27: 393.48 | D27: 702.9 | E27: 479.93 | F27: 605.82 | G27: 2333.21
A28: nov | B28: 462.95 | C28: 487.66 | D28: 489.6 | E28: 517.88 | F28: 296.35 | G28: 2254.44
A29: déc | B29: 298.55 | C29: 525.7 | D29: 542.69 | E29: 524.87 | F29: 417.66 | G29: 2309.47
A30: Grand Total | B30: 10352.74 | C30: 11240.24 | D30: 11107.38 | E30: 11861.69 | F30: 10266.35 | G30: 54828.4

Sheet Pivot table 2
A1: Row Labels | B1: Sum of Revenue
B2: 175.77
A3: Austria | B3: 25.21
A4: Bangladesh | B4: 122.21
A5: Brazil | B5: 79.88
A6: Canada | B6: 188.86
A7: Chile | B7: 29.66
A8: China | B8: 269.21
A9: Colombia | B9: 97.9
A10: Costa Rica | B10: 66.97
A11: Croatia | B11: 145.48
A12: Czech Republic | B12: 134.51
A13: Denmark | B13: 230.77
A14: Ecuador | B14: 31.32
... A54: Grand Total | B54: 54828.4

Sheet Pivot table 3
A1: Row Labels | B1: Sum of Revenue
A2: Future Science | B2: 985.61
A3: Power Journey | B3: 1026.17
A4: Power Silent | B4: 975.95
A5: Science Silent | B5: 1059.03
A6: Secrets Forest | B6: 1056.28
A7: Grand Total | B7: 5103.04

Sheet Dashboard
